INFO:root:Program started
INFO:root:Robot set up!
INFO:root:Odometry was started, PID: 8399:
INFO:root:Initial location: 0.2, 1.8, -1.5707963267948966
WARNING:root:Traceback (most recent call last):
  File "/home/pi/oscar/main.py", line 61, in main
    helpers.plot.plot_file('logs/odometry/22-12-15--11:49:12.csv', 'maps/mapa3.txt')
  File "/home/pi/oscar/helpers/plot.py", line 16, in plot_file
    df = pd.read_csv(file_name)
  File "/home/pi/.local/lib/python3.5/site-packages/pandas/io/parsers.py", line 685, in parser_f
    return _read(filepath_or_buffer, kwds)
  File "/home/pi/.local/lib/python3.5/site-packages/pandas/io/parsers.py", line 457, in _read
    parser = TextFileReader(fp_or_buf, **kwds)
  File "/home/pi/.local/lib/python3.5/site-packages/pandas/io/parsers.py", line 895, in __init__
    self._make_engine(self.engine)
  File "/home/pi/.local/lib/python3.5/site-packages/pandas/io/parsers.py", line 1135, in _make_engine
    self._engine = CParserWrapper(self.f, **self.options)
  File "/home/pi/.local/lib/python3.5/site-packages/pandas/io/parsers.py", line 1917, in __init__
    self._reader = parsers.TextReader(src, **kwds)
  File "pandas/_libs/parsers.pyx", line 382, in pandas._libs.parsers.TextReader.__cinit__
  File "pandas/_libs/parsers.pyx", line 689, in pandas._libs.parsers.TextReader._setup_parser_source
FileNotFoundError: [Errno 2] File b'logs/odometry/22-12-15--11:49:12.csv' does not exist: b'logs/odometry/22-12-15--11:49:12.csv'

WARNING:root:Abruptly stopped the robot!
INFO:root:Odometry was stopped
DEBUG:matplotlib.font_manager:findfont: Matching :family=sans-serif:style=normal:variant=normal:weight=normal:stretch=normal:size=10.0 to DejaVu Sans ('/home/pi/.local/lib/python3.5/site-packages/matplotlib/mpl-data/fonts/ttf/DejaVuSans.ttf') with score of 0.050000.
DEBUG:matplotlib.axes._base:update_title_pos
DEBUG:matplotlib.axes._base:update_title_pos
DEBUG:matplotlib.axes._base:update_title_pos
