INFO:root:MAIN: Program started
DEBUG:root:GENERATE_GRID: goal_k is: 0
INFO:root:ROBOT: Robot set up!
INFO:root:ROBOT: Odometry was started, PID: 24152:
INFO:root:MAIN: Initial location: 2.2, 2.6, -1.5707963267948966


ERROR:root:An error occurred while updating the map!
INFO:root:ROBOT forceNewPosition: Updating position to [1.8, 1.4, -1.5707963267948966]
WARNING:root:Traceback (most recent call last):
  File "/home/pi/oscar/main.py", line 63, in main
    actions.map.navigate_map(oscar, [[1, 4], [4, 4]])
  File "/home/pi/oscar/actions/map.py", line 82, in navigate_map
    [size, map] = helpers.map.read_map(robot.map_file)
  File "/home/pi/oscar/helpers/map.py", line 29, in read_map
    size = np.loadtxt(file, max_rows=1)
  File "/home/pi/.local/lib/python3.5/site-packages/numpy/lib/npyio.py", line 981, in loadtxt
    fh = np.lib._datasource.open(fname, 'rt', encoding=encoding)
  File "/home/pi/.local/lib/python3.5/site-packages/numpy/lib/_datasource.py", line 269, in open
    return ds.open(path, mode, encoding=encoding, newline=newline)
  File "/home/pi/.local/lib/python3.5/site-packages/numpy/lib/_datasource.py", line 623, in open
    raise IOError("%s not found." % path)
OSError: mapaB_CARRERA2020.txt not found.

WARNING:root:Abruptly stopped the robot!
INFO:root:Odometry was stopped
